<?xml version="1.0" encoding="UTF-8"?>
<testsuite name="MESSAGES TESTCASES"
           tests="8"
           failures="1"
           errors="0"
           skipped="0"
           time="392.948">
  <properties />
            <testcase name="create_a_new_message" time="119.623" classname="library.Messages_TestCases">
                <failure type="java.lang.AssertionError"
                  message="expected [2] but found [1]"
              >
<![CDATA[java.lang.AssertionError: expected [2] but found [1]
  org.testng.Assert.fail(Assert.java:94)
  org.testng.Assert.failNotEquals(Assert.java:513)
  org.testng.Assert.assertEqualsImpl(Assert.java:135)
  org.testng.Assert.assertEquals(Assert.java:116)
  org.testng.Assert.assertEquals(Assert.java:190)
  org.testng.Assert.assertEquals(Assert.java:200)
  library.MessagesPage.validateUpdates(MessagesPage.java:416)
  library.Messages_TestCases.create_a_new_message(Messages_TestCases.java:34)
  sun.reflect.NativeMethodAccessorImpl.invoke0(Native Method)
  sun.reflect.NativeMethodAccessorImpl.invoke(NativeMethodAccessorImpl.java:62)
  sun.reflect.DelegatingMethodAccessorImpl.invoke(DelegatingMethodAccessorImpl.java:43)
  java.lang.reflect.Method.invoke(Method.java:498)
  org.testng.internal.MethodInvocationHelper.invokeMethod(MethodInvocationHelper.java:104)
  org.testng.internal.Invoker.invokeMethod(Invoker.java:645)
  org.testng.internal.Invoker.invokeTestMethod(Invoker.java:851)
  org.testng.internal.Invoker.invokeTestMethods(Invoker.java:1177)
  org.testng.internal.TestMethodWorker.invokeTestMethods(TestMethodWorker.java:129)
  org.testng.internal.TestMethodWorker.run(TestMethodWorker.java:112)
  org.testng.TestRunner.privateRun(TestRunner.java:756)
  org.testng.TestRunner.run(TestRunner.java:610)
  org.testng.SuiteRunner.runTest(SuiteRunner.java:387)
  org.testng.SuiteRunner.access$000(SuiteRunner.java:39)
  org.testng.SuiteRunner$SuiteWorker.run(SuiteRunner.java:421)
  org.testng.internal.thread.ThreadUtil$2.call(ThreadUtil.java:64)
  java.util.concurrent.FutureTask.run(FutureTask.java:266)
  java.util.concurrent.ThreadPoolExecutor.runWorker(ThreadPoolExecutor.java:1142)
  java.util.concurrent.ThreadPoolExecutor$Worker.run(ThreadPoolExecutor.java:617)
  java.lang.Thread.run(Thread.java:745)
]]>
      </failure>

          </testcase>
  
  
            <testcase name="create_a_new_message_without_clientname" time="45.937" classname="library.Messages_TestCases" />
                <testcase name="click_cancel_message_button" time="30.620" classname="library.Messages_TestCases" />
                <testcase name="clone_message" time="18.392" classname="library.Messages_TestCases" />
                <testcase name="CCL_AE_Failtocreate_message" time="48.623" classname="library.Messages_TestCases" />
                <testcase name="create_a_new_message_without_a_message_name" time="63.999" classname="library.Messages_TestCases" />
                <testcase name="delete_message_from_db" time="3.736" classname="library.Messages_TestCases" />
                <testcase name="create_a_new_message_without_brand" time="62.018" classname="library.Messages_TestCases" />
      
</testsuite>
