<?xml version="1.0" encoding="UTF-8"?>
<testsuite name="CLIENTS TESTCASES"
           tests="8"
           failures="1"
           errors="0"
           skipped="0"
           time="281.257">
  <properties />
            <testcase name="create_a_new_client" time="56.205" classname="manage.Clients_Testcases">
                <failure type="java.lang.AssertionError"
                  message="expected [4] but found [2]"
              >
<![CDATA[java.lang.AssertionError: expected [4] but found [2]
  org.testng.Assert.fail(Assert.java:94)
  org.testng.Assert.failNotEquals(Assert.java:513)
  org.testng.Assert.assertEqualsImpl(Assert.java:135)
  org.testng.Assert.assertEquals(Assert.java:116)
  org.testng.Assert.assertEquals(Assert.java:190)
  org.testng.Assert.assertEquals(Assert.java:200)
  manage.ClientsPage.validateUpdates(ClientsPage.java:162)
  manage.Clients_Testcases.create_a_new_client(Clients_Testcases.java:28)
  sun.reflect.NativeMethodAccessorImpl.invoke0(Native Method)
  sun.reflect.NativeMethodAccessorImpl.invoke(NativeMethodAccessorImpl.java:62)
  sun.reflect.DelegatingMethodAccessorImpl.invoke(DelegatingMethodAccessorImpl.java:43)
  java.lang.reflect.Method.invoke(Method.java:498)
  org.testng.internal.MethodInvocationHelper.invokeMethod(MethodInvocationHelper.java:104)
  org.testng.internal.Invoker.invokeMethod(Invoker.java:645)
  org.testng.internal.Invoker.invokeTestMethod(Invoker.java:851)
  org.testng.internal.Invoker.invokeTestMethods(Invoker.java:1177)
  org.testng.internal.TestMethodWorker.invokeTestMethods(TestMethodWorker.java:129)
  org.testng.internal.TestMethodWorker.run(TestMethodWorker.java:112)
  org.testng.TestRunner.privateRun(TestRunner.java:756)
  org.testng.TestRunner.run(TestRunner.java:610)
  org.testng.SuiteRunner.runTest(SuiteRunner.java:387)
  org.testng.SuiteRunner.access$000(SuiteRunner.java:39)
  org.testng.SuiteRunner$SuiteWorker.run(SuiteRunner.java:421)
  org.testng.internal.thread.ThreadUtil$2.call(ThreadUtil.java:64)
  java.util.concurrent.FutureTask.run(FutureTask.java:266)
  java.util.concurrent.ThreadPoolExecutor.runWorker(ThreadPoolExecutor.java:1142)
  java.util.concurrent.ThreadPoolExecutor$Worker.run(ThreadPoolExecutor.java:617)
  java.lang.Thread.run(Thread.java:745)
]]>
      </failure>

          </testcase>
  
  
            <testcase name="create_a_new_client_witout_a_default_locales" time="38.373" classname="manage.Clients_Testcases" />
                <testcase name="create_a_new_client_without_color" time="41.544" classname="manage.Clients_Testcases" />
                <testcase name="cancel_client_add_process" time="25.149" classname="manage.Clients_Testcases" />
                <testcase name="create_a_new_client_witout_a_url" time="41.025" classname="manage.Clients_Testcases" />
                <testcase name="delete_client_from_db" time="2.281" classname="manage.Clients_Testcases" />
                <testcase name="create_a_new_client_witout_locales" time="36.419" classname="manage.Clients_Testcases" />
                <testcase name="create_a_new_client_without_name" time="40.261" classname="manage.Clients_Testcases" />
      
</testsuite>
